Workbook

Sheet DATA
A1: ※企業さんに送るときはDATAのシートは非表示にしてください！！
A2: 管理番号 | B2: 取引 ステータス | C2: 会社名(正式名称) | D2: 特定産業分野 | E2: 会社名ふりがな | F2: 会社本籍郵便番号 | G2: 会社本籍住所 （施設住所） | H2: 会社電話番号 （施設番号） | I2: 法人番号(13桁) | J2: 資本金 | K2: 代表者役職名 | L2: 代表者名 | M2: 労働保険番号(2桁-1桁-2桁-6桁-3桁) （施設労働保険番号） | N2: 雇用保険番号(4桁-6桁-1桁) （施設雇用保険番号） | O2: 月額支援料金 | P2: 業務区分 | Q2: 業種番号 | R2: 資料作成者役職・氏名 | S2: 営業担当 | T2: 年間直近売上 | U2: 常勤職員数 | V2: 営業サポート 担当者 | W2: 国内紹介料 | X2: ビザ申請料 | Y2: 海外紹介料 | Z2: 更新料 | AA2: 契約書 | AB2: 取引開始日 | AC2: 管理番号反映 | AD2: 定期健康診断時期 | AE2: 企業内担当 | AF2: 登記事項証明書 | AG2: 住民票の写し(業務執行に関与する役員) | AH2: 労働保険領収証書の写し | AI2: ①労働保険概算・増加概算・確定保険料申告書(事業主控)の写し ②申告書に対応する領収証書(口座振替結果通知ハガキ)の写し ※①・②どちらか・直近２年分が必要 | AJ2: ①社会保険料納入状況照会回答票 ②健康保険・厚生年金保険料領収証書の写し ※①・②のどちらか ※申請の日の属する月の前々月までの２４か月分 | AK2: 納税証明書(その3) ※2年経過後再提出 | AL2: 納税証明書(法人住民税) ※2年経過後再提出 | AM2: 企業様用申請書類 作成フォーム.xlsx 作成年月日 | AN2: 特定技能所属機関概要書 （参考様式第1-11号） | AO2: 特定技能所属機関の役員に関する誓約書 （参考様式第1-23号） | AP2: 2022年度メモ | AQ2: 2023年度メモ
A4: ①ここに企業マスター貼り付け↑ ↑
A5: 管理番号 | B5: 写真 | C5: 名前 (英字大文字フルネーム) | D5: 呼び方(フリガナ) | E5: 国籍 | F5: 会社名(正式名称) | G5: 生年月日 | H5: 年齢 | I5: 性別 | J5: 国内/ 海外 | K5: ビザ・就労 ステータス | L5: 本人住所 (郵便番号も入れる) | M5: 電話番号 | N5: 支援 担当者 | O5: 企業 担当者 | P5: 分野 | Q5: 在留資格 | R5: 在留期間 | S5: 在留カード番号 | T5: 在留期限 | U5: 日本語能力 | V5: パスポート番号 | W5: パスポート期限 | X5: 本国住所 | Y5: 本国電話番号 | Z5: 現在の職業 | AA5: 就業場所名 | AB5: 就業場所ふりがな | AC5: 就業場所住所 | AD5: 就業場所電話番号 | AE5: 登録支援料金 | AF5: 紹介料金 | AG5: 配偶者 の有無 | AH5: 日本に家族いるか | AI5: 初面談日 | AJ5: 内定日 | AK5: 入社日 入社してない場合「-」 | AL5: 特定技能開始月 | AM5: 退職日 辞退日 ビザ不許可日 | AN5: 施設形態（介護のみ） | AO5: 元属性 | AP5: 在籍日数 | AQ5: 期間区分 | AR5: 資格変更準備健康診断日 | AS5: 初回健康診断日 | AT5: ① 職場名 | AU5: 入社 年／月 | AV5: 退職 年／月 | AW5: ② 職場名 | AX5: 入社 年／月 | AY5: 退職 年／月 | AZ5: ③ 職場名 | BA5: 入社 年／月 | BB5: 退職 年／月
A7: ②ここに人材マスター貼り付け↑ ↑
A10: 入力 | B10: 作成日 | D10: 年 | F10: 月 | H10: 日 | J10: =CONCATENATE(C10,D10,E10,F10,G10,H10) -> 年月日
B11: 申請人年齢 | D11: 歳
G12: 関数
A13: 入力 | B13: 雇用契約開始日 | G13: =EDATE(C13,12)-1 -> 365
A15: ↓ 申請書類自動化にコピーする
A16: 特定技能外国人の報酬に関する説明書（1-4号）
A17: 申請人
A18: 経験年数 | B18: ='1-4'!K12 -> - | C18: 年
A19: ②役職,職務内容,責任 | B19: ='1-4'!D11 -> 0
A20: ⑤その他 | B20: ='1-4'!D14 -> 0
A21: 比較対象の日本人
A22: ①役職,職務内容,責任 | B22: ='1-4'!D24 -> 0
A23: 年齢 | B23: ='1-4'!E26 -> 0
A24: 性別 | B24: ='1-4'!H26 -> 0
A25: 経験年数 | B25: ='1-4'!K26 -> 0
A26: 報酬額 | B26: ='1-4'!E32 -> 0
A27: ④賃金規定の有無 | B27: ='1-4'!D30 -> 0
A28: ④賃金規定の賃金 | B28: ='1-4'!E32 -> 0
A29: ⑤同等以上である理由 | B29: ='1-4'!D33 -> 0
A30: ⑥その他 | B30: ='1-4'!D35 -> 0
A31: 比較対象じゃない日本人
A32: ①役職,職務内容,責任 | B32: ='1-4'!D49 -> 0
A33: 年齢 | B33: ='1-4'!E51 -> 0
A34: 性別 | B34: ='1-4'!H51 -> 0
A35: 経験年数 | B35: ='1-4'!K51 -> 0
A36: 報酬額 | B36: ='1-4'!E53 -> 0
A37: ④賃金規定の有無 | B37: ='1-4'!D55 -> 0
A38: ④賃金規定の賃金 | B38: ='1-4'!E57 -> 0
A39: ⑤同等以上である理由 | B39: ='1-4'!D58 -> 0
A40: ⑥その他 | B40: ='1-4'!D60 -> 0
A42: 雇用条件書(1-6号)
A43: 労働時間について
A44: 変形労働時間制 | B44: 0 | C44: 単位
A45: 所定労働時間 | B45: 0 | C45: 時間 | D45: 0 | E45: 分 | F45: 〜 | G45: 0 | H45: 時間 | I45: 0 | J45: 分 | L45: 所定労働時間数 | M45: 0 | N45: 時間 | O45: 0 | P45: 分
A46: シフト１ | B46: 0 | C46: 時間 | D46: 0 | E46: 分 | F46: 〜 | G46: 0 | H46: 時間 | I46: 0 | J46: 分 | L46: 所定労働時間数 | M46: 0 | N46: 時間 | O46: 0 | P46: 分
...

Sheet dekisugi用
A1: 労働マスター | B1: ↓ dekisugi内の所属機関ID入力
A2: 労働条件マスターのテンプレート名 | B2: 所属する特定技能所属機関ID | C2: 雇用形態(1=直接雇用 2=派遣雇用) | D2: 雇用契約期間の開始日付 | E2: 雇用契約期間の終了日付 | F2: 契約更新の有無(1=契約の更新はしない 2=自動的に更新する 3=更新する場合があり得る) | H2: 「更新する場合があり得る」の場合 - 契約期間満了時の業務量(0=該当しない 1=該当する) | J2: 「更新する場合があり得る」の場合 - 労働者の勤務成績，態度(0=該当しない 1=該当する) | L2: 「更新する場合があり得る」の場合 - 労働者の業務を遂行する能力(0=該当しない 1=該当する) | N2: 「更新する場合があり得る」の場合 - 会社の経営状況(0=該当しない 1=該当する) | P2: 「更新する場合があり得る」の場合 - 従事している業務の進捗状況(0=該当しない 1=該当する) | R2: 「更新する場合があり得る」の場合 - その他(0=該当しない 1=該当する) | S2: 「更新する場合があり得る」の場合 - その他詳細 | T2: 割増賃金率(法定超月60時間以内) | U2: 割増賃金率(法定超月60時間超) | V2: 割増賃金率(所定超) | W2: 割増賃金率(法定休日労働) | X2: 割増賃金率(法定外休日労働) | Y2: 割増賃金率(深夜労働) | Z2: 支払いについて(賃金計算のチェック) | AA2: 支払いについて(賃金計算の締日①) | AB2: 支払いについて(賃金計算の締日②) | AC2: 支払いについて(賃金の支払日チェック) | AD2: 支払いについて(賃金の支払日①) | AE2: 支払いについて(賃金の支払日②) | AF2: 支払いについて(賃金支払い方法)(1=通貨払 2=口座振込み) | AG2: メモ欄 | AH2: 雇入れ時の健康診断（年） | AI2: 雇入れ時の健康診断（月） | AJ2: 初回の定期健康診断（年） | AK2: 初回の定期健康診断（月） | AL2: その後の健康診断の実施間隔 | AM2: 賃金控除について(賃金支払い時の控除)(1=有 2=無) | AN2: 諸手当と支給額(社会保険-加入状況-厚生年金)(0=該当しない 1=該当する) | AO2: 諸手当と支給額(社会保険-加入状況-国民年金)(0=該当しない 1=該当する) | AP2: 諸手当と支給額(社会保険-加入状況-健康保険)(0=該当しない 1=該当する) | AQ2: 諸手当と支給額(社会保険-加入状況-国民健康保険)(0=該当しない 1=該当する) | AS2: 諸手当と支給額(社会保険-加入状況-その他)(0=該当しない 1=該当する) | AT2: 諸手当と支給額(社会保険-加入状況-その他詳細) | AU2: 賃金控除について(社会保険-(A)控除総額) | AV2: 諸手当と支給額(労働保険-加入状況-雇用保険)(0=該当しない 1=該当する) | AW2: 諸手当と支給額(労働保険-加入状況-労災保険)(0=該当しない 1=該当する) | AX2: 賃金控除について(労働保険-加入状況-(B)控除総額) | AY2: 賃金控除について(税金関連-加入状況-所得税)(0=該当しない 1=該当する) | AZ2: 賃金控除について(税金関連-加入状況-住民税)(0=該当しない 1=該当する) | BA2: 賃金控除について(税金関連-加入状況-(C)控除総額) | BB2: 食費について(食事、食材等の提供の有無)(1=有 2=無) | BC2: 食費について(１か月当たりの食費徴収額) | BD2: 食費について(提供する食事、食材等の具体的な内容) | BE2: 食費について(費用が実費に相当する額その他の適正な額であることの説明) | BF2: 居住費(１か月当たりの居住費徴収額)の有無 | BG2: 居住費(１か月当たりの居住費徴収額) | BH2: 居住費(提供する宿泊施設の具体的な内容)(1=自己所有物件 2=借上物件) | BI2: 居住費(費用が実費に相当する額その他の適正な額であることの説明) | BJ2: 水道光熱費(水道光熱費の徴収の有無)(1=有 2=無) | BK2: 水道光熱費(１か月当たりの水道光熱費) | BL2: 水道光熱費(水道光熱費についての詳細) | BM2: その他で負担する費用の有無(1=有 2=無) | BN2: その他負担する費用について(定期に負担する費用の内容1（負担する費用名と1か月あたりのその金額）) | BP2: その他負担する費用について(定期に負担する費用の金額1（負担する費用名と1か月あたりのその金額）) | BR2: その他負担する費用について(定期に負担する費用の内容2（負担する費用名と1か月あたりのその金額）) | BT2: その他負担する費用について(定期に負担する費用の金額2（負担する費用名と1か月あたりのその金額）) | BV2: その他負担する費用について(定期に負担する費用の内容3（負担する費用名と1か月あたりのその金額）) | BX2: その他負担する費用について(定期に負担する費用の金額3（負担する費用名と1か月あたりのその金額）) | BZ2: その他負担する費用について(定期に負担する費用の内容4（負担する費用名と1か月あたりのその金額）) | CB2: その他負担する費用について(定期に負担する費用の金額4（負担する費用名と1か月あたりのその金額）) | CD2: その他負担する費用について(定期に負担する費用の内容5（負担する費用名と1か月あたりのその金額）) | CF2: その他負担する費用について(定期に負担する費用の金額5（負担する費用名と1か月あたりのその金額）) | CH2: その他負担する費用について(定期に負担する費用に関し特定技能外国人が受ける具体的な便益の内容) | CJ2: その他負担する費用について(費用が実費に相当する額その他の適正な額であることの説明) | CL2: 主たる勤務時間(開始) | CM2: 主たる勤務時間(終了) | CN2: 休憩時間①(開始) | CO2: 休憩時間①(終了) | CP2: ∟②休憩時間(0=無 1=有) | CQ2: ∟②休憩時間(開始) | CR2: ∟②休憩時間(終了) | CS2: ∟③休憩時間(0=無 1=有) | CT2: ∟③休憩時間(開始) | CU2: ∟③休憩時間(終了) | CV2: 休憩時間合計 | CW2: 1日の所定労働時間数(時) | CX2: 1日の所定労働時間数(分) | CY2: その他(勤務時間(開始)) | CZ2: その他(勤務時間(終了)) | DA2: その他(休憩時間①(開始)) | DB2: その他(休憩時間①(終了)) | DC2: その他(∟②休憩時間(開始)) | DD2: その他(∟②休憩時間(終了)) | DE2: その他(∟③休憩時間(開始)) | DF2: その他(∟③休憩時間(終了)) | DG2: その他(休憩時間合計) | DH2: その他(1日の所定労働時間数(時)) | DI2: その他(1日の所定労働時間数(分)) | DJ2: 労働時間数と勤務日数(週間[時]) | DK2: 労働時間数と勤務日数(週間[分]) | DL2: 労働時間数と勤務日数(週間[日数]) | DM2: 労働時間数と勤務日数(月間[時]) | DN2: 労働時間数と勤務日数(月間[分]) | DO2: 労働時間数と勤務日数(月間[日数]) | DP2: 労働時間数と勤務日数(年間[時]) | DQ2: 労働時間数と勤務日数(年間[分]) | DR2: 労働時間数と勤務日数(年間[日数]) | DS2: 所定時間外労働の有無(1=無 2=有) | DT2: 労働時間に関する就業規則条項（①第 開始） | DU2: 労働時間に関する就業規則条項（①第 終了） | DV2: 労働時間に関する就業規則条項（②第 開始） | DW2: 労働時間に関する就業規則条項（②第 終了） | DX2: 労働時間に関する就業規則条項（③第 開始） | DY2: 労働時間に関する就業規則条項（③第 終了） | DZ2: 制度適用有無（変形労働時間制）(0=無 1=有) | EA2: 制度適用（変形労働時間制、単位） | EB2: 制度適用有無（交代制勤務）(0=無 1=有) | EC2: 労働時間等の備考 | ED2: 交代勤務制①適用日 | EE2: 交代勤務制①主たる勤務時間-開始 | EF2: 交代勤務制①主たる勤務時間-終了 | EG2: 交代勤務制①-①休憩時間(開始) | EH2: 交代勤務制①-①休憩時間(終了) | EI2: 交代勤務制①-②休憩時間(開始) | EJ2: 交代勤務制①-②休憩時間(終了) | EK2: 交代勤務制①-③休憩時間(開始) | EL2: 交代勤務制①-③休憩時間(終了) | EM2: 交代勤務制①1日の所定労働時間数[時] | EN2: 交代勤務制①1日の所定労働時間数[分] | EO2: 交代勤務制②適用日 | EP2: 交代勤務制②主たる勤務時間-開始 | EQ2: 交代勤務制②主たる勤務時間-終了 | ER2: 交代勤務制②-①休憩時間(開始) | ES2: 交代勤務制②-①休憩時間(終了) | ET2: 交代勤務制②-②休憩時間(開始) | EU2: 交代勤務制②-②休憩時間(終了) | EV2: 交代勤務制②-③休憩時間(開始) | EW2: 交代勤務制②-③休憩時間(終了) | EX2: 交代勤務制②1日の所定労働時間数[時] | EY2: 交代勤務制②1日の所定労働時間数[分] | EZ2: 交代勤務制③適用日 | FA2: 交代勤務制③主たる勤務時間-開始 | FB2: 交代勤務制③主たる勤務時間-終了 | FC2: 交代勤務制③-①休憩時間(開始) | FD2: 交代勤務制③-①休憩時間(終了) | FE2: 交代勤務制③-②休憩時間(開始) | FF2: 交代勤務制③-②休憩時間(終了) | FG2: 交代勤務制③-③休憩時間(開始) | FH2: 交代勤務制③-③休憩時間(終了) | FI2: 交代勤務制③1日の所定労働時間数[時] | FJ2: 交代勤務制③1日の所定労働時間数[分] | FK2: 交代勤務制④適用日 | FL2: 交代勤務制④主たる勤務時間-開始 | FM2: 交代勤務制④主たる勤務時間-終了 | FN2: 交代勤務制④-①休憩時間(開始) | FO2: 交代勤務制④-①休憩時間(終了) | FP2: 交代勤務制④-②休憩時間(開始) | FQ2: 交代勤務制④-②休憩時間(終了) | FR2: 交代勤務制④-③休憩時間(開始) | FS2: 交代勤務制④-③休憩時間(終了) | FT2: 交代勤務制④1日の所定労働時間数[時] | FU2: 交代勤務制④1日の所定労働時間数[分] | FV2: 交代勤務制⑤適用日 | FW2: 交代勤務制⑤主たる勤務時間-開始 | FX2: 交代勤務制⑤主たる勤務時間-終了 | FY2: 交代勤務制⑤-①休憩時間(開始) | FZ2: 交代勤務制⑤-①休憩時間(終了) | GA2: 交代勤務制⑤-②休憩時間(開始) | GB2: 交代勤務制⑤-②休憩時間(終了) | GC2: 交代勤務制⑤-③休憩時間(開始) | GD2: 交代勤務制⑤-③休憩時間(終了) | GE2: 交代勤務制⑤1日の所定労働時間数[時] | GF2: 交代勤務制⑤1日の所定労働時間数[分] | GG2: 交代勤務制⑥適用日 | GH2: 交代勤務制⑥主たる勤務時間-開始 | GI2: 交代勤務制⑥主たる勤務時間-終了 | GJ2: 交代勤務制⑥-①休憩時間(開始) | GK2: 交代勤務制⑥-①休憩時間(終了) | GL2: 交代勤務制⑥-②休憩時間(開始) | GM2: 交代勤務制⑥-②休憩時間(終了) | GN2: 交代勤務制⑥-③休憩時間(開始) | GO2: 交代勤務制⑥-③休憩時間(終了) | GP2: 交代勤務制⑥1日の所定労働時間数[時] | GQ2: 交代勤務制⑥1日の所定労働時間数[分] | GR2: 交代勤務制⑦適用日 | GS2: 交代勤務制⑦主たる勤務時間-開始 | GT2: 交代勤務制⑦主たる勤務時間-終了 | GU2: 交代勤務制⑦-①休憩時間(開始) | GV2: 交代勤務制⑦-①休憩時間(終了) | GW2: 交代勤務制⑦-②休憩時間(開始) | GX2: 交代勤務制⑦-②休憩時間(終了) | GY2: 交代勤務制⑦-③休憩時間(開始) | GZ2: 交代勤務制⑦-③休憩時間(終了) | HA2: 交代勤務制⑦1日の所定労働時間数[時] | HB2: 交代勤務制⑦1日の所定労働時間数[分] | HC2: 交代勤務制⑧適用日 | HD2: 交代勤務制⑧主たる勤務時間-開始 | HE2: 交代勤務制⑧主たる勤務時間-終了 | HF2: 交代勤務制⑧-①休憩時間(開始) | HG2: 交代勤務制⑧-①休憩時間(終了) | HH2: 交代勤務制⑧-②休憩時間(開始) | HI2: 交代勤務制⑧-②休憩時間(終了) | HJ2: 交代勤務制⑧-③休憩時間(開始) | HK2: 交代勤務制⑧-③休憩時間(終了) | HL2: 交代勤務制⑧1日の所定労働時間数[時] | HM2: 交代勤務制⑧1日の所定労働時間数[分] | HN2: 交代制勤務における備考 | HO2: 休日について-定例日-休日が定例日について(毎週定休制：毎週)(0=該当しない 1=該当する) | HQ2: 休日について-定例日-休日が定例日について(毎週定休制：毎週 曜日) | HR2: 休日について-定例日-休日が定例日について(日本の国民の祝日)(0=該当しない 1=該当する) | HT2: 休日について-定例日-休日が定例日について(その他)(0=該当しない 1=該当する) | HV2: 休日について-定例日-休日が定例日について(その他詳細) | HW2: 休日について-定例日-年間合計休日日数 | HX2: 休日について-定例日-休日が非定例日について(週・月あたり)(0=該当しない 1=該当する) | HZ2: 休日について-定例日-休日が非定例日について(週・月)(1=週 2=月) | IA2: 休日について-定例日-休日が非定例日について(週・月あたり日) | IB2: 休日について-定例日-休日が非定例日について(その他)(0=該当しない 1=該当する) | ID2: 休日について-定例日-休日が非定例日について(その他詳細) | IE2: 休日について-休日に関する就業規則条項(①第**条 開始) | IF2: 休日について-休日に関する就業規則条項(①第**条 終了) | IG2: 休日について-休日に関する就業規則条項(②第**条 開始) | IH2: 休日について-休日に関する就業規則条項(②第**条 終了) | II2: 休暇について-有給休暇(6か月継続勤務した場合の支給数) | IJ2: 休暇について-有給休暇(継続勤務6か月未満での支給有無)(1=有 2=無) | IK2: 休暇について-有給休暇(∟有の場合、勤続期間) | IL2: 休暇について-有給休暇(∟有の場合、支給日数) | IM2: 休暇について-その他(有給) | IN2: 休暇について-その他(無給) | IO2: 休暇に関する就業規則条項(①第**条 開始) | IP2: 休暇に関する就業規則条項(①第**条 終了) | IQ2: 休暇に関する就業規則条項(②第**条 開始) | IR2: 休暇に関する就業規則条項(②第**条 終了) | IS2: 諸手当と支給額(自己都合退職の手続きの場合) | IT2: 諸手当と支給額(退職に関する就業規則条項①第**条 開始) | IU2: 諸手当と支給額(退職に関する就業規則条項①第**条 終了) | IV2: 諸手当と支給額(退職に関する就業規則条項②第**条 開始) | IW2: 諸手当と支給額(退職に関する就業規則条項②第**条 終了) | IX2: 賃金の支払・控除額一覧(基本給（月給）加算状態) | IY2: 賃金の支払・控除額一覧(諸手当支給額(A)加算状態) | IZ2: 賃金の支払・控除額一覧(諸手当支給額(B)加算状態) | JA2: 賃金の支払・控除額一覧(諸手当支給額(C)加算状態) | JB2: 賃金の支払・控除額一覧(諸手当支給額(D)加算状態) | JC2: 賃金とその他諸手当(支払区分)(1=月給 2=日給 3=日給) | JD2: 賃金とその他諸手当(基本給-基本給) | JE2: 諸手当と支給額(基本給-月給) | JF2: 賃金とその他諸手当(基本給-日給) | JG2: 諸手当と支給額(基本給-時給) | JH2: 諸手当と支給額(諸手当と支給額①-その他手当名) | JI2: 諸手当と支給額(諸手当と支給額①-支給額) | JJ2: 諸手当と支給額(諸手当と支給額①-計算方法) | JK2: 諸手当と支給額(諸手当と支給額②-その他手当名) | JL2: 諸手当と支給額(諸手当と支給額②-支給額) | JM2: 諸手当と支給額(諸手当と支給額②-計算方法) | JN2: 諸手当と支給額(諸手当と支給額③-その他手当名) | JO2: 諸手当と支給額(諸手当と支給額③-支給額) | JP2: 諸手当と支給額(諸手当と支給額③-計算方法) | JQ2: 諸手当と支給額(諸手当と支給額④-その他手当名) | JR2: 諸手当と支給額(諸手当と支給額④-支給額) | JS2: 諸手当と支給額(諸手当と支給額④-計算方法) | JT2: 賃金とその他諸手当(諸手当と支給額⑤-その他手当名) | JU2: 賃金とその他諸手当(諸手当と支給額⑤-支給額) | JV2: 賃金とその他諸手当(諸手当と支給額⑤-計算方法) | JW2: 賃金とその他諸手当(諸手当と支給額⑥-その他手当名) | JX2: 賃金とその他諸手当(諸手当と支給額⑥-支給額) | JY2: 賃金とその他諸手当(諸手当と支給額⑥-計算方法) | JZ2: 諸手当と支給額(諸手当と支給額⑦-その他手当名) | KA2: 諸手当と支給額(諸手当と支給額⑦-支給額) | KB2: 賃金とその他諸手当(諸手当と支給額⑦-計算方法) | KC2: 賃金とその他諸手当(諸手当と支給額⑧-その他手当名) | KD2: 賃金とその他諸手当(諸手当と支給額⑧-支給額) | KE2: 賃金とその他諸手当(諸手当と支給額⑧-計算方法) | KF2: 賃金とその他諸手当(諸手当と支給額⑨-その他手当名) | KG2: 賃金とその他諸手当(諸手当と支給額⑨-支給額) | KH2: 賃金とその他諸手当(諸手当と支給額⑨-計算方法) | KI2: 賃金とその他諸手当(諸手当と支給額⑩-その他手当名) | KJ2: 賃金とその他諸手当(諸手当と支給額⑩-支給額) | KK2: 賃金とその他諸手当(諸手当と支給額⑩-計算方法) | KL2: 昇給と退職について(昇給の有無)(1=有 2=無) | KM2: 昇給と退職について(昇給した際の金額、時期等) | KN2: 昇給と退職について(期末手当（賞与）)(1=有 2=無) | KO2: 昇給と退職について(賞与の支給額) | KP2: 昇給と退職について(退職金の有無)(1=有 2=無) | KQ2: 諸手当と支給額(退職した際の金額、時期等) | KR2: 諸手当と支給額(休業手当の有無)(1=有 2=無) | KS2: 諸手当と支給額(休業手当の支給割合) | KT2: 諸手当と支給額((Ⅰ)1か月あたりの支払概算額) | KU2: 諸手当と支給額(メモ欄) | KV2: 諸手当と支給額(控除額一覧-(A)社会保険料-加算フラグ)(0=加算 1=除算) | KX2: 諸手当と支給額(控除額一覧-(B)雇用保険料-加算フラグ)(0=加算 1=除算) | KZ2: 諸手当と支給額(控除額一覧-(C)税金-加算フラグ)(0=加算 1=除算) | LA2: 諸手当と支給額(控除額一覧-食費-加算フラグ)(0=加算 1=除算) | LB2: 諸手当と支給額(控除額一覧-居住費-加算フラグ)(0=加算 1=除算) | LC2: 諸手当と支給額(控除額一覧-水道光熱費-加算フラグ)(0=加算 1=除算) | LD2: 諸手当と支給額(控除額一覧-その他（定期に負担する費用）①-加算フラグ)(0=加算 1=除算) | LF2: 諸手当と支給額(控除額一覧-その他（定期に負担する費用）②-加算フラグ)(0=加算 1=除算) | LH2: 諸手当と支給額(控除額一覧-その他（定期に負担する費用）③-加算フラグ)(0=加算 1=除算) | LJ2: 諸手当と支給額(控除額一覧-その他（定期に負担する費用）④-加算フラグ)(0=加算 1=除算) | LL2: 諸手当と支給額(控除額一覧-その他（定期に負担する費用）⑤-加算フラグ)(0=加算 1=除算) | LN2: 諸手当と支給額((Ⅱ)1か月あたりの控除総額) | LO2: 諸手当と支給額(手取り支給額 (Ⅰ)-(Ⅱ)) | LP2: 手取り支給額補足 | LQ2: 賃金の支払・控除額一覧(諸手当支給額(E)加算状態) | LR2: 賃金の支払・控除額一覧(諸手当支給額(F)加算状態) | LS2: 賃金の支払・控除額一覧(諸手当支給額(G)加算状態) | LT2: 賃金の支払・控除額一覧(諸手当支給額(H)加算状態) | LU2: 賃金の支払・控除額一覧(諸手当支給額(I)加算状態) | LV2: 賃金の支払・控除額一覧(諸手当支給額(J)加算状態)
C3: 1 | F3: 3 | H3: 1 | J3: 1 | L3: 1 | N3: 1 | P3: 0 | R3: 0 | T3: 0 | U3: 0 | V3: #REF! | W3: 0 | X3: 0 | Y3: 0 | Z3: TRUE | AA3: 0 | AC3: TRUE | AD3: 0 | AF3: 2 | AJ3: 0 | AK3: 0 | AL3: 0 | AM3: 1 | AN3: 1 | AO3: 0 | AP3: 1 | AQ3: 0 | AS3: 0 | AU3: =#REF! -> #REF! | AV3: 1 | AW3: 1 | AX3: =#REF! -> #REF! | AY3: 1 | AZ3: 0 | BA3: =#REF! -> #REF! | BB3: {=_xlfn.IFS(#REF!,"有",1,#REF!,"無",2)} -> #REF! | BC3: =#REF! -> #REF! | BD3: =#REF! -> #REF! | BE3: =#REF! -> #REF! | BF3: {=_xlfn.IFS(#REF!,"有",1,#REF!,"無",2)} -> #REF! | BG3: =#REF! -> #REF! | BH3: {=_xlfn.IFS(#REF!,"自己所有物件",1,#REF!,"借上物件",2)} -> #REF! | BI3: =#REF! -> #REF! | BJ3: {=_xlfn.IFS(#REF!,"有",1,#REF!,"無",2)} -> #REF! | BK3: =#REF! -> #REF! | BL3: =#REF! -> #REF! | BM3: {=_xlfn.IFS(#REF!,"有",1,#REF!,"無",2)} -> #REF! | BN3: =#REF! -> #REF! | BP3: =#REF! -> #REF! | BR3: =#REF! -> #REF! | BT3: =#REF! -> #REF! | BV3: =#REF! -> #REF! | BX3: =#REF! -> #REF! | CH3: =#REF! -> #REF! | CJ3: =#REF! -> #REF! | CL3: : | CM3: : | CV3: 0 | CW3: 0 | CX3: 0 | DG3: 0 | DJ3: 0 | DK3: 0 | DL3: 0 | DM3: 0 | DN3: 0 | DO3: 0 | DP3: 0 | DQ3: 0 | DR3: 0 | DS3: 2 | DT3: 0 | DU3: 0 | DV3: 0 | DW3: 0 | DX3: - | DY3: - | DZ3: 0 | EA3: 0 | EB3: 0 | EE3: : | EF3: : | EM3: 0 | EN3: 0 | EP3: : | EQ3: : | EX3: 0 | EY3: 0 | FA3: : | FB3: : | FI3: 0 | FJ3: 0 | FL3: : | FM3: : | FT3: 0 | FU3: 0 | FW3: : | FX3: : | GE3: 0 | GF3: 0 | GH3: : | GI3: : | GP3: 0 | GQ3: 0 | HO3: 0 | HQ3: 0 | HR3: 0 | HT3: 0 | HV3: 0 | HW3: 0 | HX3: 0 | HZ3: #N/A | IA3: 0 | IB3: 0 | ID3: 0 | IE3: 0 | IF3: 0 | IG3: 0 | IH3: 0 | II3: 10 | IJ3: 0 | IK3: 0 | IL3: 0 | IM3: 0 | IN3: 0 | IO3: 0 | IP3: 0 | IQ3: 0 | IR3: 0 | IS3: 0 | IT3: 0 | IU3: 0 | IV3: 0 | IW3: 0 | IX3: =#REF! -> #REF! | IY3: =#REF! -> #REF! | IZ3: =#REF! -> #REF! | JA3: =#REF! -> #REF! | JB3: =#REF! -> #REF! | JC3: 1 | JD3: 0 | JE3: =#REF! -> #REF! | JF3: =#REF! -> #REF! | JG3: =#REF! -> #REF! | JH3: =#REF! -> #REF! | JI3: =#REF! -> #REF! | JJ3: =#REF! -> #REF! | JK3: =#REF! -> #REF! | JL3: =#REF! -> #REF! | ... JS3: =#REF! -> #REF! | KL3: 0 | KM3: 0 | KN3: 0 | KO3: 0 | KP3: 0 | KQ3: 0 | KR3: 1 | KS3: 60 | KT3: =#REF! -> #REF! | KV3: 0 | KX3: 0 | KZ3: 0 | LA3: 0 | LB3: 0 | LC3: 0 | LD3: 0 | LF3: 0 | LH3: 0 | LJ3: 1 | LL3: 1 | LN3: =#REF! -> #REF! | LO3: =#REF! -> #REF!

Sheet はじめに
A1: はじめに
B2: 【注意】
B3: ・書類ご記入の前に、必ず以下のⅠ.〜Ⅲ.をご選択ください。
B4: ・その後各シートのピンク色の部分にご記入願います。
B5: （特定技能外国人を既に受入れ済みの法人様で過去のデータが残っている箇所はエクセルの記入は不要です。）
B6: ・ご取得いただく書類は1.ご案内資料PDFをご確認くださいませ。（初めて受け入れる場合のみ該当）
B7: ・複数名ご入社される予定でも、条件等変わらなけば、１つのみご記入ください。
B8: ・お受入れ済の場合、青色のタブはご入力不要です。
B11: Ⅰ. | C11: 法人/個人事業主基本情報
C12: 項目名 | D12: 詳細 | E12: 記入欄
B13: ① | C13: 特定技能外国人人材の受け入れは | D13: 初めて / 受入れ済選択
B14: ② | C14: 法人番号 | D14: 13桁
B15: ③ | C15: 資本金 | D15: 社会福祉法人の場合不要
B16: ④ | C16: 労働保険番号 | D16: 11桁又は14桁
B17: ⑤ | C17: 雇用保険適用事業所番号 | D17: 11桁（ハイフンなし）
B18: ⑥ | C18: 年間直近売上 | D18: -
B19: ⑦ | C19: 法人全体の常勤職員数 | D19: -
B22: Ⅱ. | C22: 書類の郵送先住所
B23: 選択 | D23: その他の 郵便番号 | E23: 宛先住所
B27: Ⅲ. | C27: (今回受入れ予定の)事業所情報
C28: 事業所名 | E28: 労働保険番号 | G28: 雇用保険適用事業所番号
B29: ①
B30: ②
B31: ③
B32: ④
B33: ⑤
B35: 事業所 協力確認書提出状況
B36: 未提出の場合、下記A,Bどちらかにチェックと、ピンクの箇所に情報をご入力ください。
B37: ご提出済みや、自社にてご対応いただく場合は提出日から右の欄を全てご入力ください。
B38: FALSE | C38: A：自社にて協力確認書を提出する。
B39: FALSE | C39: B：今後弊社（株式会社Funtoco）で支援委託している人材の協力確認書の提出を無料委託する。
B40: 事業所名 | D40: 提出日 | E40: 市区町村 | F40: 担当者連絡先 (部署・担当者名) | G40: メールアドレス
B41: =C29 -> 0
B42: =C30 -> 0
B43: =C31 -> 0
B44: =C32 -> 0
B45: =C33 -> 0
B46: 貴法人で提出のご対応いただく場合：フォーマットは全国統一ですが、提出方法は各市区町村によって異なります。
B47: 詳細は該当の市区町村ホームページでご確認ください。
B48: ・協力確認書とは
...

Sheet 1-4
A1: 参考様式第１－４号
A3: 特定技能外国人の報酬に関する説明書
A5: 申請人に対する報酬については，以下のとおり，「日本人が従事する場合の報酬の額と同等以
A6: 上であること」を担保しています。
A8: １ 申請人に対する報酬
A10: ①申請人の氏名 | D10: 申請人氏名
A11: ②申請人の役職，職務内容，責任の程度
A12: ③申請人の年齢，性別及び経験年数 | D12: ( | E12: - | F12: 歳) | G12: ( | H12: - | I12: ) | J12: (経験 | K12: - | L12: 年)
A13: ④申請人に対する報酬 | D13: 月給 | H13: 円／ | I13: 時間給 | L13: 円
A14: ⑤その他
A15: （注意）
A16: １ ①は，在留カード（申請人が所持していない場合は旅券）と同一の氏名を記載すること。
A17: ２ ③の経験年数は，申請人に従事させる業務に係る経験年数を記載すること。
A18: ３ ④は，月給及び時間給以外の給与形態の場合については，月給又は時間給に換算した報酬を記載すること。
A19: また，月給又は時間給のいずれかを記載することで差し支えないが，本様式において統一して記載すること。
A20: ４ ⑤は，報酬以外の諸手当等が支給されている場合など特記すべき事項がある場合に記載すること。
A22: ２ 比較対象となる日本人労働者がいる場合
A24: ①比較対象となる日本人労働者の役職，職務内容，責任の程度
A26: ②比較対象となる日本人労働者の年齢，性別及び経験年数 | D26: ( | F26: 歳) | G26: ( | I26: ) | J26: (経験 | L26: 年)
A28: ③比較対象となる日本人労働者の報酬 | D28: 月給 | H28: 円／ | I28: 時間給 | L28: 円
A30: ④賃金規程の有無及び賃金規程に基づく賃金 | B30: 規程の有無
B31: 有の場合 | D31: 賃金規程に基づき，申請人と役職，職務内容，責任の程度が同等の日本人労働者に支払われるべき報酬
D32: 月給 | H32: 円／ | I32: 時間給 | L32: 円
A33: ⑤申請人に対する報酬が日本人が従事する場合の報酬の額と同等以上であると考える理由
A35: ⑥その他 | M35: 賃金規定：『有』の場合は賃金規定写しのご用意もお願い致します。
A36: （注意） | M36: 労働基準法では、常時10人以上の従業員（パートを含む）を使用する会社に対して、
A37: １ ①は，比較対象となる日本人労働者の役職，職務内容，責任の程度が，申請人と同等であることを示すこと。 | M37: 就業規則の作成および労働基準監督署への届出を義務づけています。
A38: ２ ②の経験年数は，比較対象となる日本人労働者の経験年数を記載すること。
A39: ３ ③は，月給及び時間給以外の給与形態の場合については，月給又は時間給に換算した報酬を記載すること。
A40: また，月給又は時間給のいずれかを記載すればよいが，本様式において統一して記載すること。
A41: ４ ④は，賃金規程を作成している場合には，必ず「有」を丸印で囲むこと。また，賃金規程に基づき，申請人と
A42: 役職，職務内容，責任の程度が同等の日本人労働者に支払われるべき報酬を具体的に記載し，当該賃金規程を
A43: 参考資料として添付すること。
A44: ５ ⑥は，報酬以外の諸手当等が支給されている場合など特記すべき事項がある場合に記載すること。
A47: ３ 比較対象となる日本人労働者がいない場合
A49: ①最も近い職務を担う日本人労働者の職務内容や責任の程度
A51: ②最も近い職務を担う日本人労働者の年齢，性別及び経験年数 | D51: ( | F51: 歳) | G51: ( | I51: ) | J51: (経験 | L51: 年)
A53: ③最も近い職務を担う日本人労働者の報酬 | D53: 月給 | H53: 円／ | I53: 時間給 | L53: 円
A55: ④賃金規程の有無及び賃金規程に基づく賃金 | B55: 規程の有無
B56: 有の場合 | D56: 賃金規程に基づき，申請人と役職，職務内容，責任の程度が同等の日本人労働者に支払われるべき報酬
...

Sheet 1-6
B1: 参考様式第１－６号
A3: 雇 用 条 件 書
V6: =TODAY() -> 46163
B8: 申請者氏名 | J8: 殿
P10: 特定技能所属機関名
P11: 所在地
P12: 電話番号
P13: 代表者 役職・氏名 | Z13: ㊞
B15: Ⅰ．雇用契約期間 | AD15: １．雇用契約期間：入国予定日:入社予定の2日前の日付を弊社で入力いたします。
B16: １．雇用契約期間
D17: 年 | F17: 月 | H17: 日 | I17: 〜 | L17: 年 | N17: 月 | P17: 日 | R17: 入国予定日 | W17: 年 | Y17: 月 | AA17: 日
B19: ２．契約の更新の有無
B20: FALSE | C20: 自動的に更新する | K20: FALSE | L20: 更新する場合があり得る | T20: FALSE | U20: 契約の更新はしない
B21: ※ 上記契約の更新の有無を「更新する場合があり得る」とした場合の更新の判断基準は以下のとおりとする。
B22: FALSE | C22: 契約期間満了時の業務量 | K22: FALSE | L22: 労働者の勤務成績，態度 | T22: FALSE | U22: 労働者の業務を遂行する能力
B23: FALSE | C23: 会社の経営状況 | K23: FALSE | L23: 従事している業務の進捗状況 | T23: FALSE | U23: その他（ | AA23: ）
B25: ３． 更新上限の有無 | J25: （ | K25: □ | L25: 無 | M25: ■ | N25: 有 | O25: （最多更新 | S25: 回まで／通算契約期間 | X25: 5 | Y25: 年まで）） | AD25: ３．更新上限の有無
B26: 【労働契約法に定める同一の企業との間での通算契約期間が５年を超える有期雇用契約の締結の場合】 | AD26: ・労働基準法で明記するよう定められていますが、
B27: 本契約期間中に会社に対して期間の定めのない雇用契約（無期雇用契約）の締結の申込みをすることにより、本契約期間の末日の翌日 | AD27: 特定技能には直接関係がないため入管へ確認をとった情報で初期設定させていただいております。
B28: （ | I28: ） | J28: から、無期雇用契約での雇用に転換することができる。
B29: この場合の本契約からの労働条件の変更の有無 | L29: （ | M29: □ | N29: 無 | O29: □ | P29: 有 | Q29: （別紙２のとおり））
B31: Ⅱ．就業の場所 | AD31: Ⅱ．就業の場所
B32: FALSE | C32: 直接雇用（以下に記入） | P32: FALSE | Q32: 派遣雇用（別紙「就業条件明示書」に記入 | AD32: 就業可能性がある事業所の情報を全て記入してください。
AD33: 複数ある場合、隣のタブ[1-6別紙→II.就業の場所一覧]へご記入ください。
B34: 事業所名
B35: 所在地
B36: 連絡先
B38: Ⅲ．従事すべき業務の内容 | AD38: Ⅲ．従事すべき業務の内容
B39: １．分野 | G39: （ | H39: ◯◯◯◯分野 | R39: ） | AD39: 分野 / 業務区分：弊社にて該当分野の文言を入力いたします。
B40: ２．業務区分 | G40: （ | H40: ◯◯◯◯◯◯◯◯◯◯ | R40: ）
B43: Ⅳ．労働時間等
B44: １．始業・終業の時刻等
C45: (1)始業（ | G45: 時 | I45: 分 | J45: ） | L45: 終業（ | N45: 時 | P45: 分 | Q45: ） | V45: （1日の所定労働時間数 | Y45: 時間 | AA45: 分)
B47: (2) 【次の制度が労働者に適用される場合】 | AD47: Ⅳ．労働時間等
B48: FALSE | C48: 変形労働時間制 | H48: ： | I48: ( | R48: ） | S48: 単位の変形労働時間制 | AD48: 変形労働時間制：1年の場合、年間カレンダー・協定書の写しをデータお送りください。
B50: ※１年単位の変形労働時間制を採用している場合には，乙が十分に理解できる言語を併記した年間カレンダーの
B51: 写し及び労働基準監督署へ届け出た変形労働時間制に関する協定書の写しを添付する。
B53: FALSE | C53: 交代制として，次の勤務時間の組合せによる。
B54: 始業 （ | E54: 時 | G54: 分） | I54: 終業( | K54: 時 | M54: 分） | O54: （適用日： | S54: ,１日の所定労働時間 | Y54: 時間 | AA54: 分)
B55: 始業 （ | E55: 時 | G55: 分） | I55: 終業( | K55: 時 | M55: 分） | O55: （適用日： | S55: ,１日の所定労働時間 | Y55: 時間 | AA55: 分)
...

Sheet 1-6別紙
B1: 参考様式第１－６号 別紙
A2: 賃 金 の 支 払
B4: １．基本賃金
C5: FALSE | D5: 月給（ | I5: 円） | K5: FALSE | L5: 日給（ | R5: 円） | T5: FALSE | U5: 時間給（ | Z5: 円）
D6: ※月給・日給の場合の１時間当たりの金額 | Q6: （ | V6: 円）
D7: ※日給・時間給の場合の１か月当たりの金額 | Q7: （ | V7: 円）
B8: ２．諸手当の額及び計算方法（時間外労働の割増賃金は除く。）
B9: (a) ( | I9: 手当 | N9: 円／計算方法： | AA9: ）
B10: (b) ( | I10: 手当 | N10: 円／計算方法： | AA10: ）
B11: (c) ( | I11: 手当 | N11: 円／計算方法： | AA11: ）
B12: (d) ( | I12: 手当 | N12: 円／計算方法： | AA12: ）
B13: (e) ( | I13: 手当 | N13: 円／計算方法： | AA13: ）
B14: (f) ( | I14: 手当 | N14: 円／計算方法： | AA14: ）
B15: (g) ( | I15: 手当 | N15: 円／計算方法： | AA15: ）
B16: (h) ( | I16: 手当 | N16: 円／計算方法： | AA16: ）
AD17: ３．1か月当たりの支払概算額（1＋2） 夜勤等のその他変動する金額はご本人と相違がないよう、 含めず計算することをお勧めします。
B18: ３．１か月当たりの支払概算額（１＋２） | R18: 約 | S18: =IF(F5>=1,F5,0) + IF(R7>=1,R7,0) + SUM(K9:M16) -> 0 | X18: 円(合計) | AD18: ※海外からミャンマーの方を受け入れされる場合 ミャンマーの労働局から労働者として出国許可の手続きを行います。 スムーズにお手続きが完了するよう、現地会社で定められた最低18万円以上の概算支給額が必要となります。
B20: ４．賃金支払時に控除する項目
C21: (a) 税 金 | R21: （約 | X21: 円） | AD21: ４．賃金支払時に控除する項目
C22: (b) 社会保険料 | R22: （約 | X22: 円） | AD22: (a)税金〜(c)雇用保険料は概算額ですので 空欄でいただき弊社にて金額を入力させていただくことも可能です。
C23: (c) 雇用保険料 | R23: （約 | X23: 円）
C24: (d) 食 費 | R24: （約 | X24: 円） | AD24: (d)食費以降は徴収する項目がある場合ご記入くださいませ。
C25: (e) 居 住 費 | R25: （約 | X25: 円） | AD25: (e)居住費：法人様でご契約をいただく場合は、周辺物件の相場でおおよその金額をご記入くださいませ。
C26: (f) その他 （水道光熱費） | R26: （約 | X26: 円）
C27: ( | I27: ) | R27: （約 | X27: 円）
C28: ( | I28: ) | R28: （約 | X28: 円）
C29: ( | I29: ) | R29: （約 | X29: 円）
P30: 控除する金額 | T30: 約 | U30: =SUM(S21:W29) -> 0 | X30: 円(合計)
B31: ５．手取り支給額（３－４） | R31: 約 | S31: =S18-U30 -> 0 | X31: 円(合計)
C33: ※欠勤等がない場合であって，時間外労働の割増賃金等は除く
B34: 参考様式第1-6号 - 別紙
B35: II.就業の場所一覧
B36: 事業所名 | J36: 所在地 | V36: 連絡先
B37: =はじめに!C29 -> 0
B38: =はじめに!C30 -> 0
B39: =はじめに!C31 -> 0
B40: =はじめに!C32 -> 0
B41: =はじめに!C33 -> 0

Sheet 居住費の詳細
B1: 居住費の詳細（1-6別紙シートにて徴収がある場合のみ） | S1: １号特定技能外国人支援計画書(1-17号) の5ページ目に使用させていただきます。
B2: ①居住費の徴収の有無 | J2: =IF(M3=0,"無","有") -> 無 | S2: https://www.moj.go.jp/isa/content/001370300.pdf
B3: ②居住費として徴収する費用 | J3: 1ヶ月あたり | M3: ='1-6別紙'!S25 -> 0 | Q3: 円
B4: ③提供する宿泊施設の具体的な内容 | H4: 選択
B5: ④費用が実費に相当する額 | H5: 記入
B6: その他の適正な額であることの説明
B7: 同居人数計（本人含めた人数） | H7: 記入 | M7: 人 | S7: 同居人数例：合計4名＝2名ずつ2部屋で対応する場合は「2」
B8: （注意）
B9: １ ②から④までは，①で有にチェックを付した場合にのみ記載すること。
B10: ２ ③は，「自己所有物件」，「借上物件」のいずれかに丸印を付すこと。
B11: ３ ④は，例えば以下のような観点から記載し，説明が適切にされなければならない
B12: ・ ③が「自己所有物件」の場合： 実際に建設・改装等に要した費用，物件の耐用年数，入居する
B13: 特定技能外国人の人数等を勘案して合理的であると説明可能な額
B14: ・ ③が「借上物件」の場合： 借上げに要する賃料（管理費・共益費等を含み，敷金・礼金・保証金・
B15: 仲介手数料は含まない。以下同じ。）を，入居する特定技能外国人の人数で除した額
B19: ４ 水道光熱費
B20: ①水道光熱費の徴収の有無
B21: ②水道光熱費として徴収する費用の内容 | J21: 1ヶ月あたり約 | M21: ='1-6別紙'!S26 -> 0 | Q21: 円
B23: （注意）
B24: １ ①は，特定技能外国人本人が水道光熱費の提供業者と直接契約をする場合は無にチェックすること。
B25: ２ ②は，徴収見込額を記載すること。なお，特定技能外国人から徴収する際には，実際に
B26: 水道光熱費の提供業者に特定技能所属機関が支払った費用を，水道光熱設備を利用する者
B27: （特定技能外国人に限られない。）の人数で除した額以内の金額を徴収するものでなければならない。
B29: ５ その他特定技能外国人が定期に負担する費用
B30: ①その他特定技能外国人が | J30: =IF('1-6別紙'!S27>=1,"有","無") -> 無
B31: 定期に負担する費用の有無 | S31: 例：
B32: ②特定技能外国人が定期に | J32: I | K32: ='1-6別紙'!D27 -> 0 | M32: 費 | N32: 1ヶ月あたり約 | Q32: ='1-6別紙'!S27 -> 0 | S32: 共済会費
B33: 負担する費用の内容 | J33: Ⅱ | K33: ='1-6別紙'!D28 -> 0 | M33: 費 | N33: 1ヶ月あたり約 | Q33: ='1-6別紙'!S28 -> 0 | S33: 互助会費
J34: Ⅲ | K34: ='1-6別紙'!D29 -> 0 | M34: 費 | N34: 1ヶ月あたり約 | Q34: ='1-6別紙'!S29 -> 0
B35: ③特定技能外国人が定期に負担
B36: する費用に関し特定技能外国人
B37: が受ける具体的な便益の内容
B38: ④費用が実費に相当する額その他
B39: の適正な額であることの説明
B41: （注意）
B42: １ ②から④までは，①で有にチェックを付した場合にのみ記載すること。
B43: ２ ②は，食費・居住費・水道光熱費以外に特定技能外国人が定期に負担する費用について，
B44: 費目ごとに記載すること。
B45: ３ ③及び④は，特定技能外国人が定期に負担すること及びその負担額が合理的なものであることについて，
B46: 説明が適切にされなければならない。
...

Sheet 1-11-1
A1: 参考様式第１－１１－１号
A2: 特定技能所属機関概要書
B3: １ 所属役員 | V3: エクセル右隣のタブ[1-11-1別紙]にご記入くださいませ。
B4: 役員氏名/ふりがな/役職名 1-11-1別紙参照
B14: （注意）
B15: 役員が複数名いる場合は，その全てについて記載すること。 なお，役員を記載しきれない場合は，「別紙のとおり」と記載し，別紙を添付することとして差し支えない。
B18: 2 決算状況
F19: 前年度 | K19: 前々年度 | P19: 前々々年度
B20: 売上高 | J20: 円 | O20: 円 | S20: 円
B21: 経常損益 | J21: 円 | O21: 円 | S21: 円
B22: 純損益 | J22: 円 | O22: 円 | S22: 円
B23: 純資産 | J23: 円 | O23: 円 | S23: 円
B24: （注意）
B25: １ 個人事業主の場合には，純資産の欄に所得税青色申告決算書の貸借対照表における元入金を記載してください。
B26: ２ 前年度末において債務超過（純資産の欄がマイナス）がある場合には，中小企業診断士，税理士，公認会計士等の企業評価を行う能力があると認められる
B27: 公的資格を有する第三者が改善の見通しについて評価を行った書面を添付してください。
B29: ３ 基準適合性に係る事項
B30: （１）過去１年における特定技能外国人と同種の業務に従事する労働者の離職状況 | K30: 離職理由
K31: 自発的離職者 | P31: 非自発的離職者
F32: 日本人労働者 | O32: 名 | S32: 名
F33: 外国人労働者 | O33: 名 | S33: 名
B34: （２）前１年間の行方不明者数 | F34: 特定技能 １号及び２号 | O34: 名 | P34: うち責めに帰すべき事由による行方不明 | Q34: FALSE | R34: 該当あり
Q35: FALSE | R35: 該当なし
F36: 技能実習 | O36: 名 | P36: うち責めに帰すべき事由による行方不明 | Q36: FALSE | R36: 該当あり
Q37: FALSE | R37: 該当なし
B38: （注意）
B39: １ （１）の「自発的離職」とは，特定技能外国人の自己都合による転職や退職をいい，「非自発的離職」とは，特定技能所属機関の経営上の都合により，
B40: 人員整理を行うために希望退職を募集したり又は退職勧奨を行った場合等をいう。
B41: ２ （１）の「外国人労働者」とは，入管法別表第１の１，２及び５の表（就労資格に限る）の在留資格をもって在留する者をいう。
B42: ３ （２）は，特定技能所属機関が雇用する特定技能外国人の過去１年間における行方不明者の発生状況について，行方不明者が発生している場合はその発生
B43: 人数を，発生していない場合は０名と記載すること。また，特定技能所属機関の責めに帰すべき事由により行方不明者が発生している場合は「該当あり」
B44: に，特定技能所属機関の責めによらない理由で行方不明者が発生している場合は「該当なし」にチェックすること。
B45: ４ （２）は，特定技能所属機関が，技能実習制度における実習実施者である場合は，過去１年間における技能実習生の行方不明者の発生状況についても記載すること。
B47: ４ 中長期在留者の受入れ実績等（１号特定技能外国人支援計画の全部の実施を登録支援機関に委託する場合は記載不要） | V47: 4中長期在留者の・・・から下は記入不要です。
B48: (１) □ | C48: 過去２年間に中長期在留者（注）の受入れ又は管理を適正に行った実績を有すること | K48: 受入れ人数 | P48: 受入れ期間中の法令遵守
I49: 直近１年前 | O49: 名 | P49: □ 法令遵守
P50: □ 法令違反・行政指導あり
I51: 直近2 年前 | O51: 名 | P51: □ 法令遵守
P52: □ 法令違反・行政指導あり
I53: 添付書類 | K53: ※以下の添付書類を提出すること。 ただし、監理団体として実習監理を行っている場合や登録支援機関として１号特定 技能外国人の支援を行っている場合は、添付書類の提出不要。 □受け入れた中長期在留者リスト（参考様式第１－１１－２号）
...

Sheet 1-11-1別紙
I1: 作成責任者 役職・氏名
A2: 参考様式第１－１１－１号別紙 | U2: ・役員が複数名いる場合は，全役員をご記入ください。 ・医療法人・社会福祉法人の場合は理事・監事までの方をご記入ください。評議員の方は記入不要です。 ・こちらの書類と履歴事項全部証明書に不一致が見受けられる場合、出入国在留管理局から確認を受ける場合がございます。 その際はご協力いただけますようよろしくお願いいたします。
B4: No． | D4: 氏名 | J4: ふりがな | Q4: 役職
B5: 1
B6: 2
B7: 3
B8: 4
B9: 5
B10: 6
B11: 7
B12: 8
B13: 9
B14: 10
B15: 11
B16: 12
... B19: 15

Sheet 【介護分野】事業所概要1
K1: 介護分野の場合のみ記入
A2: 分野参考様式第１－２号 | K2: 直近で就業予定の事業所のみご記入くださいませ。
K3: ポイント：②特定技能外国人の人数が、③日本人を超えていないこと。
A4: 介護分野における業務を行わせる事業所の概要書 | K4: 協議会入会申請時にこちらの「介護分野における業務を行わせる事業所の概要書(1-2号)」と、「指定通知書」をご用意ください。
A6: １ 事業所の概要
A7: （ふりがな） ①名称
B8: =はじめに!C29 -> 0
A10: ②現在受け入れている１号特定技能外国人の数 | E10: 人
A11: ③日本人等の常勤の介護職員の数 | B11: 計 | C11: =B14+E14+G14+I14 -> 0 | E11: 人
B12: 日本人 | E12: 介護福祉士国家試験に合格したEPA介護福祉士 | G12: 在留資格「介護」により在留する者 | I12: 永住者や日本人の配偶者など，身分・地位に基づく在留資格により在留する者
D14: 人 | F14: 人 | H14: 人 | J14: 人
A15: （注意）
A16: １ 特定技能外国人が実際に業務に従事する事業所（施設・事業）について記載すること。 ２ １号特定技能外国人の人数枠の算定基準に含まれる介護職員とは、「介護等を主たる業務として行う常勤職員」を指し、介護施設の事務職員や就労支援を行う職員、看護業務を行う看護師及び准看護師はこれに含まれない。 一方、医療機関において、看護師や准看護師の指導の下に療養生活上の世話（食事、清潔、排泄、入浴、移動等）等を行う診療報酬上の看護補助者や、当該看護補助者の指導を同一病棟で行っている看護師及び准看護師は、算定基準に含まれる。
A18: ２ その他特記事項
A21: 上記の記載内容は，事実と相違ありません。
E24: 作成年月日 | G24: ='1-4'!E74 -> 46163
E25: ふりがな | G25: ='1-4'!I76 -> 0
E26: 作成責任者 | G26: ='1-4'!I77 -> 0

Sheet 【介護分野】事業所概要2
K1: 介護分野の場合のみ記入
A2: 分野参考様式第１－２号 | K2: 直近で就業予定の事業所のみご記入くださいませ。
K3: ポイント：②特定技能外国人の人数が、③日本人を超えていないこと。
A4: 介護分野における業務を行わせる事業所の概要書 | K4: 協議会入会申請時にこちらの「介護分野における業務を行わせる事業所の概要書(1-2号)」と、「指定通知書」をご用意ください。
A6: １ 事業所の概要
A7: （ふりがな） ①名称
B8: =はじめに!C30 -> 0
A10: ②現在受け入れている１号特定技能外国人の数 | E10: 人
A11: ③日本人等の常勤の介護職員の数 | B11: 計 | C11: =B14+E14+G14+I14 -> 0 | E11: 人
B12: 日本人 | E12: 介護福祉士国家試験に合格したEPA介護福祉士 | G12: 在留資格「介護」により在留する者 | I12: 永住者や日本人の配偶者など，身分・地位に基づく在留資格により在留する者
D14: 人 | F14: 人 | H14: 人 | J14: 人
A15: （注意）
A16: １ 特定技能外国人が実際に業務に従事する事業所（施設・事業）について記載すること。 ２ １号特定技能外国人の人数枠の算定基準に含まれる介護職員とは、「介護等を主たる業務として行う常勤職員」を指し、介護施設の事務職員や就労支援を行う職員、看護業務を行う看護師及び准看護師はこれに含まれない。 一方、医療機関において、看護師や准看護師の指導の下に療養生活上の世話（食事、清潔、排泄、入浴、移動等）等を行う診療報酬上の看護補助者や、当該看護補助者の指導を同一病棟で行っている看護師及び准看護師は、算定基準に含まれる。
A18: ２ その他特記事項
A21: 上記の記載内容は，事実と相違ありません。
E24: 作成年月日 | G24: ='1-4'!E74 -> 46163
E25: ふりがな | G25: ='1-4'!I76 -> 0
E26: 作成責任者 | G26: ='1-4'!I77 -> 0

Sheet 【介護分野】事業所概要3
K1: 介護分野の場合のみ記入
A2: 分野参考様式第１－２号 | K2: 直近で就業予定の事業所のみご記入くださいませ。
K3: ポイント：②特定技能外国人の人数が、③日本人を超えていないこと。
A4: 介護分野における業務を行わせる事業所の概要書 | K4: 協議会入会申請時にこちらの「介護分野における業務を行わせる事業所の概要書(1-2号)」と、「指定通知書」をご用意ください。
A6: １ 事業所の概要
A7: （ふりがな） ①名称
B8: =はじめに!C31 -> 0
A10: ②現在受け入れている１号特定技能外国人の数 | E10: 人
A11: ③日本人等の常勤の介護職員の数 | B11: 計 | C11: =B14+E14+G14+I14 -> 0 | E11: 人
B12: 日本人 | E12: 介護福祉士国家試験に合格したEPA介護福祉士 | G12: 在留資格「介護」により在留する者 | I12: 永住者や日本人の配偶者など，身分・地位に基づく在留資格により在留する者
D14: 人 | F14: 人 | H14: 人 | J14: 人
A15: （注意）
A16: １ 特定技能外国人が実際に業務に従事する事業所（施設・事業）について記載すること。 ２ １号特定技能外国人の人数枠の算定基準に含まれる介護職員とは、「介護等を主たる業務として行う常勤職員」を指し、介護施設の事務職員や就労支援を行う職員、看護業務を行う看護師及び准看護師はこれに含まれない。 一方、医療機関において、看護師や准看護師の指導の下に療養生活上の世話（食事、清潔、排泄、入浴、移動等）等を行う診療報酬上の看護補助者や、当該看護補助者の指導を同一病棟で行っている看護師及び准看護師は、算定基準に含まれる。
A18: ２ その他特記事項
A21: 上記の記載内容は，事実と相違ありません。
E24: 作成年月日 | G24: ='1-4'!E74 -> 46163
E25: ふりがな | G25: ='1-4'!I76 -> 0
E26: 作成責任者 | G26: ='1-4'!I77 -> 0

Sheet 編集不要1-23号
A1: 参考様式第１－２３号
T2: 所属機関の役員が以下の点を誓約する書類です。 1．暴力団等との関係がないこと → 犯罪組織や反社会的勢力と関係がないこと。 2．支援計画の適正実施(自社支援の場合) → 特定技能外国人に対して、法律で定められた支援内容を適切に行うこと。 3．法令順守 → 出入国管理及び難民認定法、労働法、その他関係法令を遵守すること。
A3: 特定技能所属機関の役員に関する誓約書
A4: 特定技能所属機関の役員のうち、下表に掲げる者は、特定技能外国人の受入れ業務の執行に直 接的に関与する役員ではありません。
B6: 役員氏名 | J6: ふりがな
B7: ='1-11-1別紙'!D5 -> 0 | J7: ='1-11-1別紙'!J5 -> 0
B8: ='1-11-1別紙'!D6 -> 0 | J8: ='1-11-1別紙'!J6 -> 0
B9: ='1-11-1別紙'!D7 -> 0 | J9: ='1-11-1別紙'!J7 -> 0
B10: ='1-11-1別紙'!D8 -> 0 | J10: ='1-11-1別紙'!J8 -> 0
B11: ='1-11-1別紙'!D9 -> 0 | J11: ='1-11-1別紙'!J9 -> 0
B12: ='1-11-1別紙'!D10 -> 0 | J12: ='1-11-1別紙'!J10 -> 0
B13: ='1-11-1別紙'!D11 -> 0 | J13: ='1-11-1別紙'!J11 -> 0
B14: ='1-11-1別紙'!D12 -> 0 | J14: ='1-11-1別紙'!J12 -> 0
B15: ='1-11-1別紙'!D13 -> 0 | J15: ='1-11-1別紙'!J13 -> 0
B16: ='1-11-1別紙'!D14 -> 0 | J16: ='1-11-1別紙'!J14 -> 0
B17: ='1-11-1別紙'!D15 -> 0 | J17: ='1-11-1別紙'!J15 -> 0
B18: ='1-11-1別紙'!D16 -> 0 | J18: ='1-11-1別紙'!J16 -> 0
... B21: ='1-11-1別紙'!D19 -> 0 | J21: ='1-11-1別紙'!J19 -> 0
B22: また，当該役員について，次表に掲げる出入国管理及び難民認定法（昭和26年政令第319号）第２条の５の規定に基づき，
B23: 特定技能雇用契約及び１号特定技能外国人支援計画の基準等を定める省令（平成３１年法務省令第５号）第２条第１第４号に
B24: 定められている欠格事由に該当する者ではないことを確認しました。当該役員に対して，今後，欠格事由に該当するに
B25: 至ったときは，直ちに出入国在留管理庁に申告するとともに，役員の地位を退く必要があることを説明しています。
H27: =TODAY() -> 46163
G29: 特定技能所属機関の氏名又は名称 | H29: ='1-6'!R10 -> 0
G30: 作成責任者役職・氏名 | H30: ='1-4'!H77 -> 0
B32: ○ 出入国管理及び難民認定法（昭和２６年政令第３１９号）第２条の５の規定に基づき、
B33: 特定技能雇用契約及び１号特定技能外国人支援計画の基準等を定める省令（平成３１年法務省令第５号）（抄）（特定技能雇用契約の相手方となる本邦の公私の機関の基準）
B34: 第２条第１項第４号
B35: ４ 次のいずれにも該当しないこと。
B36: イ 禁錮以上の刑に処せられ、その執行を終わり、又は執行を受けることがなくなった日から起算して５年を経過しない者
B37: ロ 次に掲げる規定又はこれらの規定に基づく命令の規定により、罰金の刑に処せられ、その執行を終わり、又は執行を受けることがなくなった日から起算して５年を経過しない者
B38: ⑴ 労働基準法第１１７条（船員職業安定法第８９条第１項又は労働者派遣法第４４条第１項の規定により適用される場合を含む。）、第１１８条第１項
B39: （労働基準法第６条及び第５６条の規定に係る部分に限る。）、第１１９条（同法第１６条、第１７条、第１８条第１項及び第３７条の規定に係る部分に限る。）
B40: 及び第１２０条（同法第１８条第７項及び第２３条から第２７条までの規定に係る部分に限る。）の規定並びにこれらの規定に係る同法第１２１条の規定
B41: ⑵ 船員法（昭和２２年法律第１００号）第１２９条（同法第８５条第１項の規定に係る部分に限る。）、第１３０条
B42: （同法第３３条、第３４条第１項、第３５条、第４５条及び第６６条（同法第８８条の２の２第４項及び第５項並びに第８８条の３第４項において準用する場合を含む。）
B43: の規定に係る部分に限る。）及び第１３１条（第１号（同法第５３条第１項及び第２項、第５４条、第５６条並びに第５８条第１項の規定に係る部分に限る。）
... B102: ヲ 法人であって、その役員のうちにイからルまでのいずれかに該当する者があるもの

Sheet 1-23
A1: 参考様式第１－２３号
A2: 特定技能所属機関の役員に関する誓約書 | H2: ※住民票を提出する役員の名前は不要です。
H3: 記入欄がたりない場合は、1-23（別紙）にご記入くださいませ。
A4: 特定技能所属機関の役員のうち，下表に掲げる者は，特定技能外国人の受入れ業務の執行に
A5: 直接的に関与する役員ではありません。
A6: （ふりがな） 役員の氏名
A22: また，当該役員について，次表に掲げる出入国管理及び難民認定法（昭和26年政令第319号）第２条の５の規定に基づき，特定技能雇用契約及び１号特定技能外国人支援計画の基準等を定める省令（平成３１年法務省令第５号）第２条第１第４号に定められている欠格事由に該当する者ではないことを確認しました。当該役員に対して，今後，欠格事由に該当するに至ったときは，直ちに出入国在留管理庁に申告するとともに，役員の地位を退く必要があることを説明しています。
B30: 特定技能所属機関の氏名又は名称 | E30: ='1-4'!E75 -> 0
B31: 作 成 責 任 者 役職・氏名 印 | E31: ='1-4'!H77 -> 0
A32: ○ 出入国管理及び難民認定法（昭和２６年政令第３１９号）第２条の５の規定に基づき，特定技能雇用契約及び１号特定技能外国人支援計画の基準等を定める省令（平成３１年法務省令第５号）（抄） （特定技能雇用契約の相手方となる本邦の公私の機関の基準） 第２条第１項第４号 ４ 次のいずれにも該当しないこと。 イ 禁錮以上の刑に処せられ，その執行を終わり，又は執行を受けることがなくなった日から起算して５年を経過しない者 ロ 次に掲げる規定又はこれらの規定に基づく命令の規定により，罰金の刑に処せられ，その執行を終わり，又は執行を受けることがなくなった日から起算して５年を経過しない者 ⑴ 労働基準法第１１７条（船員職業安定法第８９条第１項又は労働者派遣法第４４条第１項の規定により適用される場合を含む。），第１１８条第１項（労働基準法第６条及び第５６条の規定に係る部分に限る。），第１１９条（同法第１６条，第１７条，第１８条第１項及び第３７条の規定に係る部分に限る。）及び第１２０条（同法第１８条第７項及び第２３条から第２７条までの規定に係る部分に限る。）の規定並びにこれらの規定に係る同法第１２１条の規定 ⑵ 船員法（昭和２２年法律第１００号）第１２９条（同法第８５条第１項の規定に係る部分に限る。），第１３０条（同法第３３条，第３４条第１項，第３５条，第４５条及び第６６条（同法第８８条の２の２第４項及び第５項並びに第８８条の３第４項において準用する場合を含む。）の規定に係る部分に限る。）及び第１３１条（第１号（同法第５３条第１項及び第２項，第５４条，第５６条並びに第５８条第１項の規定に係る部分に限る。）及び第３号に係る部分に限る。）の規定並びにこれらの規定に係る同法第１３５条第１項の規定（これらの規定が船員職業安定法第９２条第１項の規定により適用される場合を含む。） ⑶ 職業安定法（昭和２２年法律第１４１号）第６３条，第６４条，第６５条（第１号を除く。）及び第６６条の規定並びにこれらの規定に係る同法第６７条の規定 ⑷ 船員職業安定法第１１１条から第１１５条までの規定 ⑸ 法第７１条の３，第７１条の４，第７３条の２，第７３条の４から第７４条の６の３まで，第７４条の８及び第７６条の２の規定 ⑹ 最低賃金法（昭和３４年法律第１３７号）第４０条の規定及び同条の規定に係る同法第４２条の規定 ⑺ 労働施策の総合的な推進並びに労働者の雇用の安定及び職業生活の充実等に関する法律（昭和４１年法律第１３２号）第４０条第１項（第２号に係る部分に限る。）の規定及び当該規定に係る同条第２項の規定 ⑻ 建設労働者の雇用の改善等に関する法律（昭和５１年法律第３３号）第４９条，第５０条及び第５１条（第２号及び第３号を除く。）の規定並びにこれらの規定に係る同法第５２条の規定 ⑼ 賃金の支払の確保等に関する法律（昭和５１年法律第３４号）第１８条の規定及び同条の規定に係る同法第２０条の規定 ⑽ 労働者派遣法第５８条から第６２条までの規定 ⑾ 港湾労働法（昭和６３年法律第４０号）第４８条，第４９条（第１号を除く。）及び第５１条（第２号及び第３号に係る部分に限る。）の規定並びにこれらの規定に係る同法第５２条の規定 ⑿ 中小企業における労働力の確保及び良好な雇用の機会の創出のための雇用管理の改善の促進に関する法律（平成３年法律第５７号）第１９条，第２０条及び第２１条（第３号を除く。）の規定並びにこれらの規定に係る同法第２２条の規定 ⒀ 育児休業，介護休業等育児又は家族介護を行う労働者の福祉に関する法律（平成３年法律第７６号）第６２条から第６５条までの規定 ⒁ 林業労働力の確保の促進に関する法律（平成８年法律第４５号）第３２条，第３３条及び第３４条（第３号を除く。）の規定並びにこれらの規定に係る同法第３５条の規定 ⒂ 外国人の技能実習の適正な実施及び技能実習生の保護に関する法律（平成２８年法律第８９号。以下「技能実習法」という。）第１０８条，第１０９条，第１１０条（同法第４４条の規定に係る部分に限る。），第１１１条（第１号を除く。）及び第１１２条（第１号（同法第３５条第１項の規定に係る部分に限る。）及び第６号から第１１号までに係る部分に限る。）の規定並びにこれらの規定に係る同法第１１３条の規定 ⒃ 労働者派遣法第４４条第４項の規定により適用される労働基準法第１１８条，第１１９条及び第１２１条の規定，船員職業安定法第８９条第７項の規定により適用される船員法第１２９条から第１３１条までの規定並びに労働者派遣法第４５条第７項の規定により適用される労働安全衛生法（昭和４７年法律第５７号）第１１９条及び第１２２条の規定 ハ 暴力団員による不当な行為の防止等に関する法律（平成３年法律第７７号）の規定（同法第５０条（第２号に係る部分に限る。）及び第５２条の規定を除く。）により，又は刑法（明治４０年法律第４５号）第２０４条，第２０６条，第２０８条，第２０８条の２，第２２２条若しくは第２４７条の罪若しくは暴力行為等処罰に関する法律（大正１５年法律第６０号）の罪を犯したことにより，罰金の刑に処せられ，その執行を終わり，又は執行を受けることがなくなった日から起算して５年を経過しない者 ニ 健康保険法（大正１１年法律第７０号）第２０８条，第２１３条の２若しくは第２１４条第１項，船員保険法（昭和１４年法律第７３号）第１５６条，第１５９条若しくは第１６０条第１項，労働者災害補償保険法（昭和２２年法律第５０号）第５１条前段若しくは第５４条第１項（同法第５１条前段の規定に係る部分に限る。），厚生年金保険法（昭和２９年法律第１１５号）第１０２条，第１０３条の２若しくは第１０４条第１項（同法第１０２条又は第１０３条の２の規定に係る部分に限る。），労働保険の保険料の徴収等に関する法律（昭和４４年法律第８４号）第４６条前段若しくは第４８条第１項（同法第４６条前段の規定に係る部分に限る。）又は雇用保険法（昭和４９年法律第１１６号）第８３条若しくは第８６条（同法第８３条の規定に係る部分に限る。）の規定により，罰金の刑に処せられ，その執行を終わり，又は執行を受けることがなくなった日から起算して５年を経過しない者 ホ 精神の機能の障害により特定技能雇用契約の履行を適正に行うに当たっての必要な認知，判断及び意思疎通を適切に行うことができない者 ヘ 破産手続開始の決定を受けて復権を得ない者 ト 技能実習法第１６条第１項の規定により実習認定を取り消され，当該取消しの日から起算して５年を経過しない者 チ 技能実習法第１６条第１項の規定により実習認定を取り消された者が法人である場合（同項第３号の規定により実習認定を取り消された場合については，当該法人がロ又はニに規定する者に該当することとなったことによる場合に限る。）において，当該取消しの処分を受ける原因となった事項が発生した当時現に当該法人の役員（業務を執行する社員，取締役，執行役又はこれらに準ずる者をいい，相談役，顧問その他いかなる名称を有する者であるかを問わず，法人に対し業務を執行する社員，取締役，執行役又はこれらに準ずる者と同等以上の支配力を有するものと認められる者を含む。ヲにおいて同じ。）であった者で，当該取消しの日から起算して５年を経過しないもの リ 特定技能雇用契約の締結の日前５年以内又はその締結の日以後に，次に掲げる行為その他の出入国又は労働に関する法令に関し不正又は著しく不当な行為をした者 ⑴ 外国人に対して暴行し，脅迫し又は監禁する行為 ⑵ 外国人の旅券又は在留カードを取り上げる行為 ⑶ 外国人に支給する手当又は報酬の一部又は全部を支払わない行為 ⑷ 外国人の外出その他私生活の自由を不当に制限する行為 ⑸ ⑴から⑷までに掲げるもののほか，外国人の人権を著しく侵害する行為 ⑹ 外国人に係る出入国又は労働に関する法令に関して行われた不正又は著しく不当な行為に関する事実を隠蔽する目的又はその事業活動に関し外国人に法第３章第１節若しくは第２節の規定による証明書の交付，上陸許可の証印若しくは許可，同章第４節の規定による上陸の許可若しくは法第４章第１節若しくは第２節若しくは第５章第３節の規定による許可を受けさせる目的で，偽造若しくは変造された文書若しくは図画若しくは虚偽の文書若しくは図画を行使し，又は提供する行為 ⑺ 特定技能雇用契約に基づく当該外国人の本邦における活動に関連して，保証金の徴収若しくは財産の管理又は当該特定技能雇用契約の不履行に係る違約金を定める契約その他不当に金銭その他の財産の移転を予定する契約を締結する行為 ⑻ 外国人若しくはその配偶者，直系若しくは同居の親族その他当該外国人と社会生活において密接な関係を有する者との間で，特定技能雇用契約に基づく当該外国人の本邦における活動に関連して，保証金の徴収その他名目のいかんを問わず金銭その他の財産の管理をする者若しくは当該特定技能雇用契約の不履行について違約金を定める契約その他の不当に金銭その他の財産の移転を予定する契約を締結した者又はこれらの行為をしようとする者からの紹介を受けて，当該外国人と当該特定技能雇用契約を締結する行為 ⑼ 法第１９条の１８の規定による届出をせず，又は虚偽の届出をする行為 ⑽ 法第１９条の２０第１項の規定による報告若しくは帳簿書類の提出若しくは提示をせず，若しくは虚偽の報告若しくは虚偽の帳簿書類の提出若しくは提示をし，又は同項の規定による質問に対して答弁をせず，若しくは虚偽の答弁をし，若しくは同項の規定による検査を拒み，妨げ，若しくは忌避する行為 ⑾ 法第１９条の２１第１項の規定による処分に違反する行為 ヌ 暴力団員による不当な行為の防止等に関する法律第２条第６号に規定する暴力団員（以下「暴力団員」という。）又は暴力団員でなくなった日から５年を経過しない者（以下「暴力団員等」という。） ル 営業に関し成年者と同一の行為能力を有しない未成年者であって，その法定代理人がイからヌまで又はヲのいずれかに該当するもの ヲ 法人であって，その役員のうちにイからルまでのいずれかに該当する者があるもの ワ （略）

Sheet 1-23 (別紙)
A1: 参考様式第１－２３号
A2: 特定技能所属機関の役員に関する誓約書
A4: 特定技能所属機関の役員のうち，下表に掲げる者は，特定技能外国人の受入れ業務の執行に
A5: 直接的に関与する役員ではありません。
A6: （ふりがな） 役員の氏名 | H6: 記入欄がたりない場合は、こちらにご記入くださいませ。
